<?xml version="1.0" ?>
<!-- =================================================================================== -->
<!-- |    This document was autogenerated by xacro from robot.xacro                    | -->
<!-- |    EDITING THIS FILE BY HAND IS NOT RECOMMENDED                                 | -->
<!-- =================================================================================== -->
<robot name="l91">
  <material name="black">
    <color rgba="0.0 0.0 0.0 1.0"/>
  </material>
  <material name="blue">
    <color rgba="0.0 0.0 0.8 1.0"/>
  </material>
  <material name="green">
    <color rgba="0.0 0.8 0.0 1.0"/>
  </material>
  <material name="grey">
    <color rgba="0.2 0.2 0.2 1.0"/>
  </material>
  <material name="silver">
    <color rgba="0.9137254901960784 0.9137254901960784 0.8470588235294118 1.0"/>
  </material>
  <material name="orange">
    <color rgba="1.0 0.4235294117647059 0.0392156862745098 1.0"/>
  </material>
  <material name="brown">
    <color rgba="0.8705882352941177 0.8117647058823529 0.7647058823529411 1.0"/>
  </material>
  <material name="red">
    <color rgba="0.8 0.0 0.0 1.0"/>
  </material>
  <material name="white">
    <color rgba="1.0 1.0 1.0 1.0"/>
  </material>

  <link name="base">
    <visual>
      <origin rpy="0 0 0" xyz="0 0 0"/>
      <geometry>
        <box size="0.001 0.001 0.001"/>
      </geometry>
    </visual>
  </link>

  <link name="body">
    <visual>
      <origin rpy="0 0 0" xyz="0 0 0"/>
      <geometry>
        <mesh filename="../meshes_angular/body.dae" scale="1 1 1"/>
      </geometry>
    </visual>
    <collision>
      <origin rpy="0 0 0" xyz="0 0 0"/>
      <geometry>
        <box size="0.236 0.19 0.109"/>
      </geometry>
    </collision>
    <inertial>
      <origin rpy="0 0 0" xyz="0.0273 -0.000242 0.0143"/>
      <mass value="4.03"/>
        <!--<inertia ixx="0.0185" ixy="-0.000173" ixz="-0.0102" iyy="0.0517" iyz="-2.83e-05" izz="0.0483"/>-->
      <inertia ixx=" 0.018531986839446832 " ixy=" 0" ixz="0" iyy=" 0.05163302332903658 " iyz=" 0" izz=" 0.0483349898315166 "
/>
    </inertial>
  </link>
      <joint name="head_joint" type="fixed" >
        <parent link="body" />
        <child link="head" />
        <origin rpy="0 0 0" xyz="0 0 0" />
    </joint>
    <link name="head">
        <collision>
            <origin rpy="0 0.3 0" xyz="0.256 0 0.120" />
            <geometry>
                <box size="0.07 0.09 0.060" />
            </geometry>
        </collision>
        <collision>
            <origin rpy="0 0.3 0" xyz="0.205 0 0.170" />
            <geometry>
                <box size="0.020 0.100 0.080" />
            </geometry>
        </collision>
    </link>

  <link name="imu_link">
    <inertial>
      <mass value="0.001"/>
      <origin rpy="0 0 0" xyz="0 0 0"/>
      <inertia ixx="0.0001" ixy="0" ixz="0" iyy="0.0001" iyz="0" izz="0.0001"/>
    </inertial>
    <visual>
      <origin rpy="0 0 0" xyz="0 0 0"/>
      <geometry>
        <box size="0.001 0.001 0.001"/>
      </geometry>
      <material name="red"/>
    </visual>
    <collision>
      <origin rpy="0 0 0" xyz="0 0 0"/>
      <geometry>
        <box size=".001 .001 .001"/>
      </geometry>
    </collision>
  </link>

  <link name="FL_abad">
    <visual>
      <origin rpy="0 0 0" xyz="0 0 0"/>
      <geometry>
        <mesh filename="../meshes_angular/abad.dae" scale="1 1 1"/>
      </geometry>
    </visual>
    <inertial>
      <origin rpy="0 0 0" xyz="-0.00392 0.015 -0.000306"/>
      <mass value="0.354"/>
      <inertia ixx="0.00019" ixy="-2.7e-05" ixz="-3.44e-07" iyy="0.000276" iyz="1.95e-06" izz="0.000233"/>
    </inertial>
  </link>

  <!-- this link is only for abad rotor inertial -->
  <link name="FL_abad_rotor">
    <inertial>
      <origin rpy="0 0 0" xyz="0 0 0"/>
      <mass value="0.0567"/>
      <inertia ixx="2.53e-05" ixy="0" ixz="0" iyy="2.53e-05" iyz="0" izz="4.78e-05"/>
    </inertial>
  </link>

<!--  &lt;!&ndash; this link is only for collision &ndash;&gt;-->
<!--  <link name="FL_hip_shoulder">-->
<!--    <collision>-->
<!--      <origin rpy="1.5707963267948966 0 0" xyz="0 0.02 0.002"/>-->
<!--      <geometry>-->
<!--        <sphere radius="0.04"/>-->
<!--      </geometry>-->
<!--    </collision>-->
<!--  </link>-->

  <link name="FL_hip">
    <visual>
      <origin rpy="0 0 0" xyz="0 0 0"/>
      <geometry>
        <mesh filename="../meshes_angular/hip.dae" scale="1 1 1"/>
      </geometry>
    </visual>
    <collision>
       <origin rpy="0 1.5707963267948966 0" xyz="0 -0.005 -0.06"/>
      <geometry>
         <box size="0.12 0.025 0.05"/>
      </geometry>
    </collision>
    <inertial>
      <origin rpy="0 0 0" xyz="0.00212 0.0212 -0.0184"/>
      <mass value="0.482"/>
      <inertia ixx="0.00101" ixy="2.23e-05" ixz="3.85e-05" iyy="0.000983" iyz="-0.000199" izz="0.000347"/>
    </inertial>
  </link>

  <!-- this link is only for hip rotor inertial -->
  <link name="FL_hip_rotor">
    <inertial>
      <origin rpy="0 0 0" xyz="0 0 0"/>
      <mass value="0.0567"/>
      <inertia ixx="2.53e-05" ixy="0" ixz="0" iyy="2.53e-05" iyz="0" izz="4.78e-05"/>
    </inertial>
  </link>

  <!-- this link is only for knee rotor inertial -->
  <link name="FL_knee_rotor">
    <inertial>
      <origin rpy="0 0 0" xyz="0 0 0"/>
      <mass value="0.0567"/>
      <inertia ixx="2.53e-05" ixy="0" ixz="0" iyy="2.53e-05" iyz="0" izz="4.78e-05"/>
    </inertial>
  </link>

  <link name="FL_knee">
    <visual>
      <origin rpy="0 0 0" xyz="0 0 0"/>
      <geometry>
        <mesh filename="../meshes_angular/knee.dae" scale="1 1 1"/>
      </geometry>
    </visual>
    <collision>
      <origin rpy="0 3.3 0" xyz="0 0 -0.091705"/>
      <geometry>
        <box size="0.016 0.016 0.16"/>
      </geometry>
    </collision>
<!--    <collision name="FL_knee_rubber">-->
<!--      <origin rpy="0 3.141592653589793 0" xyz="0.01 0 -0.007"/>-->
<!--      <geometry>-->
<!--        <sphere radius="0.016"/>-->
<!--      </geometry>-->
<!--    </collision>-->
    <inertial>
      <origin rpy="0 0 0" xyz="-0.0006 4.72e-05 -0.0893"/>
      <mass value="0.116"/>
      <inertia ixx="0.000668" ixy="3e-09" ixz="-2.37e-05" iyy="0.000674" iyz="-6.03e-07" izz="1.54e-05"/>
    </inertial>
  </link>

  <link name="FL_foot">
    <visual>
      <origin rpy="0 0 0" xyz="0 0 0"/>
      <geometry>
        <sphere radius="0.009"/>
      </geometry>
    </visual>
    <collision>
      <origin rpy="0 0 0" xyz="0 0 0"/>
      <geometry>
        <sphere radius="0.018"/>
      </geometry>
    </collision>
    <inertial>
      <mass value="0.06"/>
      <inertia ixx="9.6e-06" ixy="0.0" ixz="0.0" iyy="9.6e-06" iyz="0.0" izz="9.6e-06"/>
    </inertial>
  </link>

  <link name="FR_abad">
    <visual>
      <origin rpy="3.141592653589793 0 0" xyz="0 0 0"/>
      <geometry>
        <mesh filename="../meshes_angular/abad.dae" scale="1 1 1"/>
      </geometry>
    </visual>
    <inertial>
      <origin rpy="0 0 0" xyz="-0.00392 -0.015 -0.000306"/>
      <mass value="0.354"/>
      <inertia ixx="0.00019" ixy="2.7e-05" ixz="-3.44e-07" iyy="0.000276" iyz="-1.95e-06" izz="0.000233"/>
    </inertial>
  </link>

  <!-- this link is only for abad rotor inertial -->
  <link name="FR_abad_rotor">
    <inertial>
      <origin rpy="0 0 0" xyz="0 0 0"/>
      <mass value="0.0567"/>
      <inertia ixx="2.53e-05" ixy="0" ixz="0" iyy="2.53e-05" iyz="0" izz="4.78e-05"/>
    </inertial>
  </link>

  <!-- this link is only for collision -->
<!--  <link name="FR_hip_shoulder">-->
<!--    <collision>-->
<!--      <origin rpy="1.5707963267948966 0 0" xyz="0 -0.02 0.002"/>-->
<!--      <geometry>-->
<!--        <sphere radius="0.04"/>-->
<!--      </geometry>-->
<!--    </collision>-->
<!--  </link>-->

  <link name="FR_hip">
    <visual>
      <origin rpy="0 0 0" xyz="0 0 0"/>
      <geometry>
        <mesh filename="../meshes_angular/hip_mirror.dae" scale="1 1 1"/>
      </geometry>
    </visual>
    <collision>
       <origin rpy="0 1.5707963267948966 0" xyz="0 0.005 -0.06"/>
      <geometry>
         <box size="0.12 0.025 0.05"/>
      </geometry>
    </collision>
    <inertial>
      <origin rpy="0 0 0" xyz="0.00212 -0.0212 -0.0184"/>
      <mass value="0.482"/>
      <inertia ixx="0.00101" ixy="-2.23e-05" ixz="3.85e-05" iyy="0.000983" iyz="0.000199" izz="0.000347"/>
    </inertial>
  </link>

  <!-- this link is only for hip rotor inertial -->
  <link name="FR_hip_rotor">
    <inertial>
      <origin rpy="0 0 0" xyz="0 0 0"/>
      <mass value="0.0567"/>
      <inertia ixx="2.53e-05" ixy="0" ixz="0" iyy="2.53e-05" iyz="0" izz="4.78e-05"/>
    </inertial>
  </link>

  <!-- this link is only for knee rotor inertial -->
  <link name="FR_knee_rotor">
    <inertial>
      <origin rpy="0 0 0" xyz="0 0 0"/>
      <mass value="0.0567"/>
      <inertia ixx="2.53e-05" ixy="0" ixz="0" iyy="2.53e-05" iyz="0" izz="4.78e-05"/>
    </inertial>
  </link>

  <link name="FR_knee">
    <visual>
      <origin rpy="0 0 0" xyz="0 0 0"/>
      <geometry>
        <mesh filename="../meshes_angular/knee.dae" scale="1 1 1"/>
      </geometry>
    </visual>
    <collision>
      <origin rpy="0 3.3 0" xyz="0 0 -0.091705"/>
      <geometry>
        <box size="0.016 0.016 0.16"/>
      </geometry>
    </collision>
<!--    <collision name="FR_knee_rubber">-->
<!--      <origin rpy="0 3.141592653589793 0" xyz="0.01 0 -0.007"/>-->
<!--      <geometry>-->
<!--        <sphere radius="0.016"/>-->
<!--      </geometry>-->
<!--    </collision>-->
    <inertial>
      <origin rpy="0 0 0" xyz="-0.0006 4.72e-05 -0.0893"/>
      <mass value="0.116"/>
      <inertia ixx="0.000668" ixy="3e-09" ixz="-2.37e-05" iyy="0.000674" iyz="-6.03e-07" izz="1.54e-05"/>
    </inertial>
  </link>

  <link name="FR_foot">
    <visual>
      <origin rpy="0 0 0" xyz="0 0 0"/>
      <geometry>
        <sphere radius="0.009"/>
      </geometry>
    </visual>
    <collision>
      <origin rpy="0 0 0" xyz="0 0 0"/>
      <geometry>
        <sphere radius="0.018"/>
      </geometry>
    </collision>
    <inertial>
      <mass value="0.06"/>
      <inertia ixx="9.6e-06" ixy="0.0" ixz="0.0" iyy="9.6e-06" iyz="0.0" izz="9.6e-06"/>
    </inertial>
  </link>

  <link name="RL_abad">
    <visual>
      <origin rpy="0 3.141592653589793 0" xyz="0 0 0"/>
      <geometry>
        <mesh filename="../meshes_angular/abad.dae" scale="1 1 1"/>
      </geometry>
    </visual>
    <inertial>
      <origin rpy="0 0 0" xyz="0.00392 0.015 -0.000306"/>
      <mass value="0.354"/>
      <inertia ixx="0.00019" ixy="2.7e-05" ixz="3.44e-07" iyy="0.000276" iyz="1.95e-06" izz="0.000233"/>
    </inertial>
  </link>

  <!-- this link is only for abad rotor inertial -->
  <link name="RL_abad_rotor">
    <inertial>
      <origin rpy="0 0 0" xyz="0 0 0"/>
      <mass value="0.0567"/>
      <inertia ixx="2.53e-05" ixy="0" ixz="0" iyy="2.53e-05" iyz="0" izz="4.78e-05"/>
    </inertial>
  </link>

  <!-- this link is only for collision -->
<!--  <link name="RL_hip_shoulder">-->
<!--    <collision>-->
<!--      <origin rpy="1.5707963267948966 0 0" xyz="0 0.02 0.002"/>-->
<!--      <geometry>-->
<!--        <sphere radius="0.04"/>-->
<!--      </geometry>-->
<!--    </collision>-->
<!--  </link>-->

  <link name="RL_hip">
    <visual>
      <origin rpy="0 0 0" xyz="0 0 0"/>
      <geometry>
        <mesh filename="../meshes_angular/hip.dae" scale="1 1 1"/>
      </geometry>
    </visual>
    <collision>
       <origin rpy="0 1.5707963267948966 0" xyz="0 -0.005 -0.06"/>
      <geometry>
         <box size="0.12 0.025 0.05"/>
      </geometry>
    </collision>
    <inertial>
      <origin rpy="0 0 0" xyz="0.00212 0.0212 -0.0184"/>
      <mass value="0.482"/>
      <inertia ixx="0.00101" ixy="2.23e-05" ixz="3.85e-05" iyy="0.000983" iyz="-0.000199" izz="0.000347"/>
    </inertial>
  </link>

  <!-- this link is only for hip rotor inertial -->
  <link name="RL_hip_rotor">
    <inertial>
      <origin rpy="0 0 0" xyz="0 0 0"/>
      <mass value="0.0567"/>
      <inertia ixx="2.53e-05" ixy="0" ixz="0" iyy="2.53e-05" iyz="0" izz="4.78e-05"/>
    </inertial>
  </link>

  <!-- this link is only for knee rotor inertial -->
  <link name="RL_knee_rotor">
    <inertial>
      <origin rpy="0 0 0" xyz="0 0 0"/>
      <mass value="0.0567"/>
      <inertia ixx="2.53e-05" ixy="0" ixz="0" iyy="2.53e-05" iyz="0" izz="4.78e-05"/>
    </inertial>
  </link>

  <link name="RL_knee">
    <visual>
      <origin rpy="0 0 0" xyz="0 0 0"/>
      <geometry>
        <mesh filename="../meshes_angular/knee.dae" scale="1 1 1"/>
      </geometry>
    </visual>
    <collision>
      <origin rpy="0 3.3 0" xyz="0 0 -0.091705"/>
      <geometry>
        <box size="0.016 0.016 0.16"/>
      </geometry>
    </collision>
<!--    <collision name="RL_knee_rubber">-->
<!--      <origin rpy="0 3.141592653589793 0" xyz="0.01 0 -0.007"/>-->
<!--      <geometry>-->
<!--        <sphere radius="0.016"/>-->
<!--      </geometry>-->
<!--    </collision>-->
    <inertial>
      <origin rpy="0 0 0" xyz="-0.0006 4.72e-05 -0.0893"/>
      <mass value="0.116"/>
      <inertia ixx="0.000668" ixy="3e-09" ixz="-2.37e-05" iyy="0.000674" iyz="-6.03e-07" izz="1.54e-05"/>
    </inertial>
  </link>

  <link name="RL_foot">
    <visual>
      <origin rpy="0 0 0" xyz="0 0 0"/>
      <geometry>
        <sphere radius="0.009"/>
      </geometry>
    </visual>
    <collision>
      <origin rpy="0 0 0" xyz="0 0 0"/>
      <geometry>
        <sphere radius="0.018"/>
      </geometry>
    </collision>
    <inertial>
      <mass value="0.06"/>
      <inertia ixx="9.6e-06" ixy="0.0" ixz="0.0" iyy="9.6e-06" iyz="0.0" izz="9.6e-06"/>
    </inertial>
  </link>

  <link name="RR_abad">
    <visual>
      <origin rpy="3.141592653589793 3.141592653589793 0" xyz="0 0 0"/>
      <geometry>
        <mesh filename="../meshes_angular/abad.dae" scale="1 1 1"/>
      </geometry>
    </visual>
    <inertial>
      <origin rpy="0 0 0" xyz="0.00392 -0.015 -0.000306"/>
      <mass value="0.354"/>
      <inertia ixx="0.00019" ixy="-2.7e-05" ixz="3.44e-07" iyy="0.000276" iyz="-1.95e-06" izz="0.000233"/>
    </inertial>
  </link>

  <!-- this link is only for abad rotor inertial -->
  <link name="RR_abad_rotor">
    <inertial>
      <origin rpy="0 0 0" xyz="0 0 0"/>
      <mass value="0.0567"/>
      <inertia ixx="2.53e-05" ixy="0" ixz="0" iyy="2.53e-05" iyz="0" izz="4.78e-05"/>
    </inertial>
  </link>

  <!-- this link is only for collision -->
<!--  <link name="RR_hip_shoulder">-->
<!--    <collision>-->
<!--      <origin rpy="1.5707963267948966 0 0" xyz="0 -0.02 0.002"/>-->
<!--      <geometry>-->
<!--        <sphere radius="0.04"/>-->
<!--      </geometry>-->
<!--    </collision>-->
<!--  </link>-->

  <link name="RR_hip">
    <visual>
      <origin rpy="0 0 0" xyz="0 0 0"/>
      <geometry>
        <mesh filename="../meshes_angular/hip_mirror.dae" scale="1 1 1"/>
      </geometry>
    </visual>
    <collision>
       <origin rpy="0 1.5707963267948966 0" xyz="0 0.005 -0.06"/>
      <geometry>
         <box size="0.12 0.025 0.05"/>
      </geometry>
    </collision>
    <inertial>
      <origin rpy="0 0 0" xyz="0.00212 -0.0212 -0.0184"/>
      <mass value="0.482"/>
      <inertia ixx="0.00101" ixy="-2.23e-05" ixz="3.85e-05" iyy="0.000983" iyz="0.000199" izz="0.000347"/>
    </inertial>
  </link>

  <!-- this link is only for hip rotor inertial -->
  <link name="RR_hip_rotor">
    <inertial>
      <origin rpy="0 0 0" xyz="0 0 0"/>
      <mass value="0.0567"/>
      <inertia ixx="2.53e-05" ixy="0" ixz="0" iyy="2.53e-05" iyz="0" izz="4.78e-05"/>
    </inertial>
  </link>

  <!-- this link is only for knee rotor inertial -->
  <link name="RR_knee_rotor">
    <inertial>
      <origin rpy="0 0 0" xyz="0 0 0"/>
      <mass value="0.0567"/>
      <inertia ixx="2.53e-05" ixy="0" ixz="0" iyy="2.53e-05" iyz="0" izz="4.78e-05"/>
    </inertial>
  </link>

  <link name="RR_knee">
    <visual>
      <origin rpy="0 0 0" xyz="0 0 0"/>
      <geometry>
        <mesh filename="../meshes_angular/knee.dae" scale="1 1 1"/>
      </geometry>
    </visual>
    <collision>
      <origin rpy="0 3.3 0" xyz="0 0 -0.091705"/>
      <geometry>
        <box size="0.016 0.016 0.16"/>
      </geometry>
    </collision>
<!--    <collision name="RR_knee_rubber">-->
<!--      <origin rpy="0 3.141592653589793 0" xyz="0.01 0 -0.007"/>-->
<!--      <geometry>-->
<!--        <sphere radius="0.016"/>-->
<!--      </geometry>-->
<!--    </collision>-->
    <inertial>
      <origin rpy="0 0 0" xyz="-0.0006 4.72e-05 -0.0893"/>
      <mass value="0.116"/>
      <inertia ixx="0.000668" ixy="3e-09" ixz="-2.37e-05" iyy="0.000674" iyz="-6.03e-07" izz="1.54e-05"/>
    </inertial>
  </link>

  <link name="RR_foot">
    <visual>
      <origin rpy="0 0 0" xyz="0 0 0"/>
      <geometry>
        <sphere radius="0.009"/>
      </geometry>
    </visual>
    <collision>
      <origin rpy="0 0 0" xyz="0 0 0"/>
      <geometry>
        <sphere radius="0.018"/>
      </geometry>
    </collision>
    <inertial>
      <mass value="0.06"/>
      <inertia ixx="9.6e-06" ixy="0.0" ixz="0.0" iyy="9.6e-06" iyz="0.0" izz="9.6e-06"/>
    </inertial>
  </link>

  <joint name="floating_base" type="fixed">
    <origin rpy="0 0 0" xyz="0 0 0"/>
    <parent link="base"/>
    <child link="body"/>
  </joint>
  <joint name="imu_joint" type="fixed">
    <parent link="body"/>
    <child link="imu_link"/>
    <origin rpy="0 0 0" xyz="0 0 0"/>
  </joint>

  <joint name="FL_abad_joint" type="revolute">
    <origin rpy="0 0 0" xyz="0.16 0.042 0"/>
    <parent link="body"/>
    <child link="FL_abad"/>
    <axis xyz="1 0 0"/>
    <dynamics damping="0" friction="0"/>
    <limit effort="12.0001" lower="-0.7" upper="0.68" velocity="32.0"/>
  </joint>
  <joint name="FL_abad_rotor_fix" type="fixed">
    <origin rpy="0 0 0" xyz="-0.0642303 0 0"/>
    <parent link="FL_abad"/>
    <child link="FL_abad_rotor"/>
  </joint>
<!--  <joint name="FL_abad_fixed" type="fixed">-->
<!--    <origin rpy="0 0 0" xyz="0 0.059 0"/>-->
<!--    <parent link="FL_abad"/>-->
<!--    <child link="FL_hip_shoulder"/>-->
<!--  </joint>-->
  <joint name="FL_hip_joint" type="revolute">
    <origin rpy="0 0 3.141592653589793" xyz="0 0.094 0"/>
    <parent link="FL_abad"/>
    <child link="FL_hip"/>
    <axis xyz="0 1 0"/>
    <dynamics damping="0" friction="0"/>
<!--    <limit effort="12.0001" lower="-2.0" upper="1.3264502315156903" velocity="32.0"/>-->
  <limit effort="12.0001" lower="-2.82" upper="1.36" velocity="32.0"/>
  </joint>
  <joint name="FL_hip_rotor_fix" type="fixed">
    <origin rpy="0 0 0" xyz="0 0.07577 0"/>
    <parent link="FL_hip"/>
    <child link="FL_hip_rotor"/>
  </joint>
  <joint name="FL_knee_rotor_fix" type="fixed">
    <origin rpy="0 0 0" xyz="0 0.0342303 0"/>
    <parent link="FL_hip"/>
    <child link="FL_knee_rotor"/>
  </joint>
  <joint name="FL_knee_joint" type="revolute">
    <origin rpy="0 0 0" xyz="0 0 -0.12"/>
    <parent link="FL_hip"/>
    <child link="FL_knee"/>
    <axis xyz="0 1 0"/>
    <dynamics damping="0" friction="0"/>
    <limit effort="12.0001" lower="0.54" upper="2.58" velocity="32.0"/>
  </joint>
  <joint name="FL_foot_fixed" type="fixed" dont_collapse="true">
    <origin rpy="0 0 0" xyz="-0.0055 0 -0.17390999999999998"/>
    <parent link="FL_knee"/>
    <child link="FL_foot"/>
  </joint>

  <joint name="FR_abad_joint" type="revolute">
    <origin rpy="0 0 0" xyz="0.16 -0.042 0"/>
    <parent link="body"/>
    <child link="FR_abad"/>
    <axis xyz="1 0 0"/>
    <dynamics damping="0" friction="0"/>
    <limit effort="12.0001" lower="-0.68" upper="0.7" velocity="32.0"/>
  </joint>
  <joint name="FR_abad_rotor_fix" type="fixed">
    <origin rpy="0 0 0" xyz="-0.0642303 0 0"/>
    <parent link="FR_abad"/>
    <child link="FR_abad_rotor"/>
  </joint>
<!--  <joint name="FR_abad_fixed" type="fixed">-->
<!--    <origin rpy="0 0 0" xyz="0 -0.059 0"/>-->
<!--    <parent link="FR_abad"/>-->
<!--    <child link="FR_hip_shoulder"/>-->
<!--  </joint>-->
  <joint name="FR_hip_joint" type="revolute">
    <origin rpy="0 0 3.141592653589793" xyz="0 -0.094 0"/>
    <parent link="FR_abad"/>
    <child link="FR_hip"/>
    <axis xyz="0 1 0"/>
    <dynamics damping="0" friction="0"/>
<!--    <limit effort="12.0001" lower="-2.0" upper="1.3264502315156903" velocity="32.0"/>-->
      <limit effort="12.0001" lower="-2.82" upper="1.36" velocity="32.0"/>
  </joint>
  <joint name="FR_hip_rotor_fix" type="fixed">
    <origin rpy="0 0 0" xyz="0 -0.07577 0"/>
    <parent link="FR_hip"/>
    <child link="FR_hip_rotor"/>
  </joint>
  <joint name="FR_knee_rotor_fix" type="fixed">
    <origin rpy="0 0 0" xyz="0 -0.0342303 0"/>
    <parent link="FR_hip"/>
    <child link="FR_knee_rotor"/>
  </joint>
  <joint name="FR_knee_joint" type="revolute">
    <origin rpy="0 0 0" xyz="0 0 -0.12"/>
    <parent link="FR_hip"/>
    <child link="FR_knee"/>
    <axis xyz="0 1 0"/>
    <dynamics damping="0" friction="0"/>
    <limit effort="12.0001" lower="0.54" upper="2.58" velocity="32.0"/>
  </joint>
  <joint name="FR_foot_fixed" type="fixed" dont_collapse="true">
    <origin rpy="0 0 0" xyz="-0.0055 0 -0.17390999999999998"/>
    <parent link="FR_knee"/>
    <child link="FR_foot"/>
  </joint>

  <joint name="RL_abad_joint" type="revolute">
    <origin rpy="0 0 0" xyz="-0.16 0.042 0"/>
    <parent link="body"/>
    <child link="RL_abad"/>
    <axis xyz="1 0 0"/>
    <dynamics damping="0" friction="0"/>
    <limit effort="12.0001" lower="-0.69" upper="0.93" velocity="32.0"/>
  </joint>
  <joint name="RL_abad_rotor_fix" type="fixed">
    <origin rpy="0 0 0" xyz="0.0642303 0 0"/>
    <parent link="RL_abad"/>
    <child link="RL_abad_rotor"/>
  </joint>
<!--  <joint name="RL_abad_fixed" type="fixed">-->
<!--    <origin rpy="0 0 0" xyz="0 0.059 0"/>-->
<!--    <parent link="RL_abad"/>-->
<!--    <child link="RL_hip_shoulder"/>-->
<!--  </joint>-->
  <joint name="RL_hip_joint" type="revolute">
    <origin rpy="0 0 3.141592653589793" xyz="0 0.094 0"/>
    <parent link="RL_abad"/>
    <child link="RL_hip"/>
    <axis xyz="0 1 0"/>
    <dynamics damping="0" friction="0"/>
<!--    <limit effort="12.0001" lower="-2.0" upper="1.3264502315156903" velocity="32.0"/>-->
    <limit effort="12.0001" lower="-3.15" upper="1.01" velocity="32.0"/>
  </joint>
  <joint name="RL_hip_rotor_fix" type="fixed">
    <origin rpy="0 0 0" xyz="0 0.07577 0"/>
    <parent link="RL_hip"/>
    <child link="RL_hip_rotor"/>
  </joint>
  <joint name="RL_knee_rotor_fix" type="fixed">
    <origin rpy="0 0 0" xyz="0 0.0342303 0"/>
    <parent link="RL_hip"/>
    <child link="RL_knee_rotor"/>
  </joint>
  <joint name="RL_knee_joint" type="revolute">
    <origin rpy="0 0 0" xyz="0 0 -0.12"/>
    <parent link="RL_hip"/>
    <child link="RL_knee"/>
    <axis xyz="0 1 0"/>
    <dynamics damping="0" friction="0"/>
    <limit effort="12.0001" lower="0.54" upper="2.58" velocity="32.0"/>
  </joint>
  <joint name="RL_foot_fixed" type="fixed" dont_collapse="true">
    <origin rpy="0 0 0" xyz="-0.0055 0 -0.17390999999999998"/>
    <parent link="RL_knee"/>
    <child link="RL_foot"/>
  </joint>

  <joint name="RR_abad_joint" type="revolute">
    <origin rpy="0 0 0" xyz="-0.16 -0.042 0"/>
    <parent link="body"/>
    <child link="RR_abad"/>
    <axis xyz="1 0 0"/>
    <dynamics damping="0" friction="0"/>
    <limit effort="12.0001" lower="-0.94" upper="0.69" velocity="32.0"/>
  </joint>
  <joint name="RR_abad_rotor_fix" type="fixed">
    <origin rpy="0 0 0" xyz="0.0642303 0 0"/>
    <parent link="RR_abad"/>
    <child link="RR_abad_rotor"/>
  </joint>
<!--  <joint name="RR_abad_fixed" type="fixed">-->
<!--    <origin rpy="0 0 0" xyz="0 -0.059 0"/>-->
<!--    <parent link="RR_abad"/>-->
<!--    <child link="RR_hip_shoulder"/>-->
<!--  </joint>-->
  <joint name="RR_hip_joint" type="revolute">
    <origin rpy="0 0 3.141592653589793" xyz="0 -0.094 0"/>
    <parent link="RR_abad"/>
    <child link="RR_hip"/>
    <axis xyz="0 1 0"/>
    <dynamics damping="0" friction="0"/>
<!--    <limit effort="12.0001" lower="-2.0" upper="1.3264502315156903" velocity="32.0"/>-->
    <limit effort="12.0001" lower="-3.15" upper="1.01" velocity="32.0"/>

  </joint>
  <joint name="RR_hip_rotor_fix" type="fixed">
    <origin rpy="0 0 0" xyz="0 -0.07577 0"/>
    <parent link="RR_hip"/>
    <child link="RR_hip_rotor"/>
  </joint>
  <joint name="RR_knee_rotor_fix" type="fixed">
    <origin rpy="0 0 0" xyz="0 -0.0342303 0"/>
    <parent link="RR_hip"/>
    <child link="RR_knee_rotor"/>
  </joint>
  <joint name="RR_knee_joint" type="revolute">
    <origin rpy="0 0 0" xyz="0 0 -0.12"/>
    <parent link="RR_hip"/>
    <child link="RR_knee"/>
    <axis xyz="0 1 0"/>
    <dynamics damping="0" friction="0"/>
    <limit effort="12.0001" lower="0.54" upper="2.58" velocity="32.0"/>
  </joint>
  <joint name="RR_foot_fixed" type="fixed" dont_collapse="true">
    <origin rpy="0 0 0" xyz="-0.0055 0 -0.17390999999999998"/>
    <parent link="RR_knee"/>
    <child link="RR_foot"/>
  </joint>

</robot>